In C++, exceptions provide a way to handle errors or exceptional situations that occur during the execution of a program. When an error occurs, the program can "throw" an exception to indicate that something unexpected has happened. This exception can then be "caught" and handled by appropriate code elsewhere in the program.

Here's a detailed explanation of exceptions in C++:

-> Syntax and Concepts:

1. Throwing Exceptions:
   
   Exceptions are thrown using the `throw` keyword followed by an expression. This expression can be of any data type, including built-in types, objects, or pointers.

   
   throw SomeException(); // Throws an instance of SomeException
   

2. Catching Exceptions:

   Exceptions are caught using `try` and `catch` blocks. Code that might throw an exception is placed inside the `try` block, and the appropriate `catch` block is used to handle the exception if it occurs.

   
   try {
       // Code that might throw an exception
   } catch (SomeException& e) {
       // Handle the exception
   }
   

3. Exception Objects:

   When an exception is thrown, an object is created to represent the exception. This object can contain information about the error, such as an error message or error code. The type of the exception object determines which `catch` block will handle it.

   
   class SomeException : public std::exception {
   public:
       const char* what() const noexcept override {
           return "Some exception occurred";
       }
   };
   

4. Standard Exception Types:

   C++ provides several standard exception types defined in the `<stdexcept>` header, such as `std::runtime_error`, `std::logic_error`, etc. These are often used to represent common types of errors.

   
   #include <stdexcept>
   
   try {
       if (condition) {
           throw std::runtime_error("Runtime error occurred");
       }
   } catch (std::runtime_error& e) {
       // Handle runtime error
   }
   

5. Catch-All Blocks:

   You can have a catch block that catches any type of exception. This is useful for handling unexpected exceptions or for providing a generic error-handling mechanism.

   
   try {
       // Code that might throw an exception
   } catch (...) {
       // Catch any exception
   }
   

6. Rethrowing Exceptions:

   Sometimes, you may want to catch an exception, perform some additional processing, and then rethrow the same exception or a different one.

   
   try {
       // Code that might throw an exception
   } catch (SomeException& e) {
       // Handle the exception
       throw; // Rethrow the same exception
   } catch (std::exception& e) {
       // Handle other exceptions
       throw DifferentException(); // Rethrow a different exception
   }
   

7. Stack Unwinding:

   When an exception is thrown, the program's execution stack is "unwound." This means that the program jumps back up the call stack, looking for a suitable `catch` block to handle the exception.

   
   void foo() {
       try {
           bar();
       } catch (...) {
           // Handle exception in foo() if not caught in bar()
       }
   }
   

-> Example:


#include <iostream>
#include <stdexcept>

void divide(int a, int b) {
    if (b == 0) {
        throw std::invalid_argument("Division by zero");
    }
    std::cout << "Result: " << a / b << std::endl;
}

int main() {
    try {
        divide(10, 0);
    } catch (const std::exception& e) {
        std::cerr << "Exception caught: " << e.what() << std::endl;
    }
    return 0;
}


In this example, if `b` is zero, the `divide` function throws an `std::invalid_argument` exception. The exception is caught in the `main` function's `try-catch` block, and an appropriate error message is displayed.

That's a comprehensive overview of exceptions in C++, covering syntax, concepts, and usage.